Workbook

Sheet Annual Review
B3: Swifty ZA | C3: Swifty UK/IE | D3: Swifty B2B
A4: GGR Sports
A5: GGR Casino
A7: Platform Revenue
A8: Vickers | D8: 28000
A9: TigerBet | D9: 25000
A10: Metabet | D10: 25000
A11: Swifty | D11: 20000
A13: Expenses
A15: Affiliates
A18: Software Services
A19: Platform Cost | C19: 20000
A22: Staff
A23: C2B | C23: 50000
A24: Dev | D24: 50000
A26: Platform Services
A27: Everymatrix
A28: AWS | D28: 24000
A29: Podium
A30: NIXXE | D30: 6000
A31: Transunion | D31: 5000
A32: Sumsub | D32: 10000
A33: Customer.io

Sheet B2C
B1: B2C - Fy.2026
D3: ZAR to GBP | E3: 0.04555 | G3: ZAR to GBP | H3: 0.04658 | J3: ZAR to GBP | K3: 0.04405
C5: January | F5: February | I5: March
C6: Swifty Africa (ZAR) | D6: Swifty IE/UK (GBP) | E6: Total (GBP) | F6: Swifty Africa (ZAR) | G6: Swifty IE/UK (GBP) | H6: Total (GBP) | I6: Swifty Africa (ZAR) | J6: Swifty IE/UK (GBP) | K6: Total (GBP)
B7: Gaming Revenue
B8: Sports | C8: -201966.94 | D8: =63994.02+(20349.51/1.15) -> 81689.246 | E8: =D8+(C8*$E$3) -> 72489.652 | F8: -195284.29 | G8: =62334.33+(21236.21/1.141) -> 80946.258 | H8: =G8+(F8*H$3) -> 71849.916 | I8: -236533.5 | J8: =79104.27+(23400.29/1.151) -> 99434.67 | K8: =J8+(I8*K$3) -> 89015.369
B9: Casino | C9: 409107.07 | D9: =108779.53+(-1654.02/1.15) -> 107341.25 | E9: =D9+(C9*$E$3) -> 125976.08 | F9: 889923.34 | G9: =74955.6+(127.5/1.141) -> 75067.344 | H9: =G9+(F9*H$3) -> 116519.97 | I9: 2061651 | J9: =149281.23+(3100.89/1.151) -> 151975.31 | K9: =J9+(I9*K$3) -> 242791.04
B11: Total Revenue | C11: =SUM(C8:C10) -> 207140.13 | D11: =SUM(D8:D10) -> 189030.5 | E11: =SUM(E8:E10) -> 198465.73 | F11: =SUM(F8:F10) -> 694639.05 | G11: =SUM(G8:G10) -> 156013.6 | H11: =SUM(H8:H10) -> 188369.89 | I11: =SUM(I8:I10) -> 1825117.5 | J11: =SUM(J8:J10) -> 251409.98 | K11: =SUM(K8:K10) -> 331806.41
B13: Costs and expenses:
B14: Salaries | C14: ='Expense breakdown'!D69 -> 263386 | D14: ='Expense breakdown'!D83+'Expense breakdown'!D95 -> 65176.353 | E14: =D14+(C14*$E$3) -> 77173.585 | F14: ='Expense breakdown'!E69 -> 223386 | G14: ='Expense breakdown'!E83+'Expense breakdown'!E95 -> 53750.681 | H14: =G14+(F14*H$3) -> 64156.001 | I14: ='Expense breakdown'!F69 -> 223386 | J14: ='Expense breakdown'!F83+'Expense breakdown'!F95 -> 52640.465 | K14: =J14+(I14*K$3) -> 62480.618
B15: Affiliates | C15: ='Expense breakdown'!D133 -> 108627.83 | D15: ='Expense breakdown'!D122 -> 67668.98 | E15: =D15+(C15*$E$3) -> 72616.977 | F15: ='Expense breakdown'!E133 -> 19816 | G15: ='Expense breakdown'!E122 -> 67185.74 | H15: =G15+(F15*H$3) -> 68108.769 | I15: ='Expense breakdown'!F133 -> 98388 | J15: ='Expense breakdown'!F122 -> 71486.639 | K15: =J15+(I15*K$3) -> 75820.63
B16: Marketing | C16: ='Expense breakdown'!D143 -> 103156.84 | D16: ='Expense breakdown'!D155 -> 6755 | E16: =D16+(C16*$E$3) -> 11453.794 | F16: ='Expense breakdown'!E143 -> 270391.24 | G16: ='Expense breakdown'!E155 -> 6678.3173 | H16: =G16+(F16*H$3) -> 19273.141 | I16: ='Expense breakdown'!F143 -> 664950 | J16: ='Expense breakdown'!F155 -> 8285.929 | K16: =J16+(I16*K$3) -> 37576.977
B17: Software & Data feeds | C17: ='Expense breakdown'!D167 -> 172889.05 | D17: ='Expense breakdown'!D182 -> 29868.757 | E17: =D17+(C17*$E$3) -> 37743.853 | F17: ='Expense breakdown'!E167 -> 352764.33 | G17: ='Expense breakdown'!E182 -> 33287.037 | H17: =G17+(F17*H$3) -> 49718.799 | I17: ='Expense breakdown'!F167 -> 632359.5 | J17: ='Expense breakdown'!F182 -> 41376.072 | K17: =J17+(I17*K$3) -> 69231.508
B18: Consultancy expenses | C18: 0 | D18: ='Expense breakdown'!D192 -> 4730.98 | E18: =D18+(C18*$E$3) -> 4730.98 | F18: 0 | G18: ='Expense breakdown'!E192 -> 3446.94 | H18: =G18+(F18*H$3) -> 3446.94 | I18: 0 | J18: ='Expense breakdown'!F192 -> 92.94 | K18: =J18+(I18*K$3) -> 92.94
B19: Rent | C19: ='Expense breakdown'!D207 -> 33273.34 | D19: ='Expense breakdown'!D199 -> 2024.6096 | E19: =D19+(C19*$E$3) -> 3540.2102 | F19: ='Expense breakdown'!E207 -> 34615.26 | G19: ='Expense breakdown'!E199 -> 2026.6673 | H19: =G19+(F19*H$3) -> 3639.0461 | I19: ='Expense breakdown'!F207 -> 25680.78 | J19: ='Expense breakdown'!F199 -> 2024.3829 | K19: =J19+(I19*K$3) -> 3155.6213
B20: Bank charges | C20: ='Expense breakdown'!D238 -> 126052.26 | D20: ='Expense breakdown'!D229 -> 22103.713 | E20: =D20+(C20*$E$3) -> 27845.393 | F20: ='Expense breakdown'!E238 -> 220489.02 | G20: ='Expense breakdown'!E229 -> 17849.373 | H20: =G20+(F20*H$3) -> 28119.751 | I20: ='Expense breakdown'!F238 -> 194352.6 | J20: ='Expense breakdown'!F229 -> 19949.294 | K20: =J20+(I20*K$3) -> 28510.526
B21: Hospitality expenses | C21: ='Expense breakdown'!D257 -> 9848.37 | D21: ='Expense breakdown'!D248 -> 669.93452 | E21: =D21+(C21*$E$3) -> 1118.5278 | F21: ='Expense breakdown'!E257 -> 2634.81 | G21: ='Expense breakdown'!E248 -> 2776.8162 | H21: =G21+(F21*H$3) -> 2899.5456 | I21: ='Expense breakdown'!F257 -> 6494.77 | J21: ='Expense breakdown'!F248 -> 6519.8 | K21: =J21+(I21*K$3) -> 6805.8946
B22: Taxes | C22: 0 | D22: ='Expense breakdown'!D284 -> 45902.751 | E22: =D22+(C22*$E$3) -> 45902.751 | F22: 0 | G22: ='Expense breakdown'!E284 -> 39719.106 | H22: =G22+(F22*H$3) -> 39719.106 | I22: 0 | J22: ='Expense breakdown'!F284 -> 56402.855 | K22: =J22+(I22*K$3) -> 56402.855
B23: Other expenses | C23: ='Expense breakdown'!D265 -> 9422.2 | D23: ='Expense breakdown'!D274 -> 1623.5049 | E23: =D23+(C23*$E$3) -> 2052.6861 | F23: ='Expense breakdown'!E265 -> 7252.18 | G23: ='Expense breakdown'!E274 -> 1311.5784 | H23: =G23+(F23*H$3) -> 1649.3849 | I23: ='Expense breakdown'!F265 -> 12631.97 | J23: ='Expense breakdown'!F274 -> 1684.5359 | K23: =J23+(I23*K$3) -> 2240.9742
B25: Total Expenses | C25: =SUM(C14:C24) -> 826655.89 | D25: =SUM(D14:D24) -> 246524.58 | E25: =SUM(E14:E24) -> 284178.76 | F25: =SUM(F14:F24) -> 1131348.8 | G25: =SUM(G14:G24) -> 228032.26 | H25: =SUM(H14:H24) -> 280730.48 | I25: =SUM(I14:I24) -> 1858243.6 | J25: =SUM(J14:J24) -> 260462.91 | K25: =SUM(K14:K24) -> 342318.54
C27: =C11-C25 -> -619515.76 | D27: =D11-D25 -> -57494.084 | E27: =E11-E25 -> -85713.027 | F27: =F11-F25 -> -436709.79 | G27: =G11-G25 -> -72018.653 | H27: =H11-H25 -> -92360.595 | I27: =I11-I25 -> -33126.111 | J27: =J11-J25 -> -9052.9286 | K27: =K11-K25 -> -10512.134

Sheet B1
B1: Swifty Africa | C1: Swifty Sports | D1: Swifty UK | E1: Total
G2: ZAR to GBP
A3: Trading Revenue | G3: AED to GBP | H3: 0.2
A4: GGR Sports | B4: -278760 | D4: 67652.51
A5: GGR Casino | B5: 940986 | D5: 42555.92
A6: GGR Sports IE | C6: 21365.28 | D6: 18587.794
A7: GGR Casino IE | C7: 8427.3 | D7: 7331.751
A9: Platform revenue | E9: =20000+610.2+463.45+7500 -> 28573.65
A10: Total revenue | B10: =SUM(B3:B9) -> 662226 | C10: =SUM(C3:C9) -> 29792.58 | D10: 136127.97 | E10: =SUM(E3:E9) -> 28573.65
A12: Expenses
A13: Agents Commission
A14: Affiliate expenses
A15: IGX Ltd (Ryan) | D15: 15000
A16: Invendium Ltd | D16: 11023.82
A17: NBK UK | D17: 4000
A18: Betselect.co.uk | D18: 1404.44
A19: Zealium Media | B19: 17000
A20: Aliaksei Machulski | B20: =1200/0.05108 -> 23492.561
A22: Salaries & Staff Expenses
A23: Staff | D23: =70000-27500 -> 42500 | E23: 7500
A24: Bonuses | D24: 0
A26: Software and Support services
A27: Lsports
A28: SIS | D28: 2120.19
A29: Pragmatic play/ Tamaris | D29: 1555.6296
A30: Dama NV (Softswiss) | D30: 2175
A31: ATR | D31: 4785.87
A32: RMG | D32: 1408.53
A33: Ecomaccess
A34: Laptops | D34: 3743.7666
A35: Timetastic | D35: 37.474
A36: Atlassian | D36: 175.752
A37: MicroSoft | D37: 674.196
A38: Adobe | D38: 100.64
A39: Chat GPT | D39: 414.864
A40: MongoDB | D40: 60.436
A41: Midjourney | D41: 7.98
A42: Customer.IO | D42: 926.192
A43: IPSTACK | D43: 61.558
A44: TWILIO | D44: 1710.542
...

Sheet Manage Services
A2: Revenue
A3: Vickers | B3: 7500 | C3: 15000
A4: TigerBet | B4: 20000 | C4: 20000
A5: Metabet | B5: -
A6: Swifty | B6: 20000 | C6: 20000
A7: Company X | B7: -
A8: Total | B8: =SUM(B3:B7) -> 47500 | C8: =C6+C4+C3 -> 55000
A10: Resources
A11: Operations | B11: 5300
A12: Trading | B12: 15650
A13: Casino | B13: 4167
A14: Compliance | B14: 12000
A15: Customer Service | B15: 4005
A16: Finance | B16: 4465
A17: Graphics | B17: 2100
A18: Affiliates | B18: 1750
A19: Total | B19: =SUM(B11:B18) -> 49437

Sheet B2B Old
A1: Revenue | B1: Amount | C1: Currency
A2: Vickers | B2: 20000 | C2: GBP
A3: TigerBet | B3: 20000 | C3: GBP
A4: Metabet | B4: 20000 | C4: GBP
A5: Swifty | B5: 20000 | C5: GBP
A6: Company X | B6: 45000 | C6: GBP
B7: =SUM(B2:B6) -> 125000 | C7: GBP
A9: Costs
A10: Staff | B10: 50425 | C10: EUR
A11: AWS | B11: 20000 | C11: EUR
A12: EM | B12: 15000 | C12: EUR
A13: PA | B13: =(120000+168000)/12 -> 24000 | C13: EUR
A14: RDR | B14: 5000 | C14: EUR
A15: Bet Builder | B15: 5000 | C15: EUR
B16: =SUM(B10:B15) -> 119425 | C16: GBP

Sheet B2B
B1: B2B - Fy.2026
B3: (figures in GBP)
C4: January | D4: February | E4: March | F4: April | G4: May | H4: June | I4: July | J4: August | K4: September | L4: October | M4: November | N4: December | O4: Total | P4: Reco
B5: B2B sales revenue
B6: Vickers | C6: =35162+20640 -> 55802 | D6: =32116+16497 -> 48613 | E6: =44106.38+20205 -> 64311.38 | O6: =SUM(C6:N6) -> 168726.38
B7: Metabet | C7: =5000+18161 -> 23161 | D7: =5000+25829 -> 30829 | E7: =5000+25549 -> 30549 | O7: =SUM(C7:N7) -> 84539
B8: Noirvale/Tigerplay | C8: =5000+37538 -> 42538 | D8: =5000+60352 -> 65352 | E8: =5000+45668 -> 50668 | O8: =SUM(C8:N8) -> 158558
B10: Total Revenue | C10: =SUM(C6:C9) -> 121501 | D10: =SUM(D6:D9) -> 144794 | E10: =SUM(E6:E9) -> 145528.38 | F10: =SUM(F6:F9) -> 0 | G10: =SUM(G6:G9) -> 0 | H10: =SUM(H6:H9) -> 0 | I10: =SUM(I6:I9) -> 0 | J10: =SUM(J6:J9) -> 0 | ... O10: =SUM(O6:O9) -> 411823.38
B12: Costs and expenses:
B13: PA Media | C13: ='Expense breakdown'!D44 -> 27264.757 | D13: ='Expense breakdown'!E44 -> 27264.757 | E13: ='Expense breakdown'!F44 -> 27264.757 | O13: =SUM(C13:N13) -> 81794.27 | P13: =#REF! -> #REF! | Q13: =O13-P13 -> #REF!
B14: AWS | C14: ='Expense breakdown'!D45 -> 18269.643 | D14: ='Expense breakdown'!E45 -> 18274.539 | E14: ='Expense breakdown'!F45 -> 15798.48 | O14: =SUM(C14:N14) -> 52342.663 | P14: =#REF! -> #REF! | Q14: =O14-P14 -> #REF!
B15: Everymatrix | C15: ='Expense breakdown'!D46 -> 13043.478 | D15: ='Expense breakdown'!E46 -> 13146.363 | E15: ='Expense breakdown'!F46 -> 13032.146 | O15: =SUM(C15:N15) -> 39221.987
B16: Transunion | C16: ='Expense breakdown'!D47 -> 2806.5 | D16: ='Expense breakdown'!E47 -> 2001 | E16: ='Expense breakdown'!F47 -> 2733 | O16: =SUM(C16:N16) -> 7540.5
B17: Sumsub | C17: =SUM('Expense breakdown'!D292:D293)/1.15 -> 4727.2174 | D17: =SUM('Expense breakdown'!E292:E293)/1.141 -> 3702.8834 | E17: =SUM('Expense breakdown'!F292:F293)/1.141 -> 4665.8107 | O17: =SUM(C17:N17) -> 13095.912
B18: Pragmatic play | C18: =SUM('Expense breakdown'!D303:D305)/1.15 -> 17102.409 | D18: =SUM('Expense breakdown'!E303:E305)/1.141 -> 13928.107 | E18: =SUM('Expense breakdown'!F303:F305)/1.151 -> 16676.5 | O18: =SUM(C18:N18) -> 47707.016
B19: Evolution | C19: ='Expense breakdown'!D326/1.15 -> 3968.6957 | D19: ='Expense breakdown'!E326/1.141 -> 10749.395 | E19: ='Expense breakdown'!F326/1.151 -> 11902.7
B20: Nixxe | C20: =SUM('Expense breakdown'!D315:D317)/1.15 -> 3913.0435 | D20: =SUM('Expense breakdown'!E315:E317)/1.141 -> 6157.26 | E20: =SUM('Expense breakdown'!F315:F317)/1.151 -> 7332.66 | O20: =SUM(C20:N20) -> 17402.963
B21: NE Room | C21: ='Expense breakdown'!D48 -> 24362.609 | D21: ='Expense breakdown'!E48 -> 27017.528 | E21: ='Expense breakdown'!F48 -> 33020.851 | O21: =SUM(C21:N21) -> 84400.989
B22: Lukasz | C22: ='Expense breakdown'!D49 -> 4782.6087 | D22: ='Expense breakdown'!E49 -> 4820.333 | E22: ='Expense breakdown'!F49 -> 4778.4535 | O22: =SUM(C22:N22) -> 14381.395
B23: Lusine | C23: ='Expense breakdown'!D50 -> 4173.913 | D23: ='Expense breakdown'!E50 -> 4206.8361 | E23: ='Expense breakdown'!F50 -> 4170.2867 | O23: =SUM(C23:N23) -> 12551.036
B24: Banda Pixels | C24: ='Expense breakdown'!D51 -> 7585.1478 | D24: ='Expense breakdown'!E51 -> 8107.5723 | E24: ='Expense breakdown'!F51 -> 8568.1147 | O24: =SUM(C24:N24) -> 24260.835
B25: Data feeds/SportsR | C25: ='Expense breakdown'!D52 -> 4347.8261 | D25: ='Expense breakdown'!E52 -> 4382.1209 | E25: ='Expense breakdown'!F52 -> 4344.0487 | O25: =SUM(C25:N25) -> 13073.996
B26: Software expenses | C26: ='Expense breakdown'!D39 -> 8718.5833 | D26: ='Expense breakdown'!E39 -> 8405.6404 | E26: ='Expense breakdown'!F39 -> 11022.468 | O26: =SUM(C26:N26) -> 28146.692
O27: =SUM(C27:N27) -> 0 | P27: =#REF! -> #REF! | Q27: =O27-P27 -> #REF!
B28: Total Expenses | C28: =SUM(C13:C27) -> 145066.43 | D28: =SUM(D13:D27) -> 152164.34 | E28: =SUM(E13:E27) -> 165310.28 | F28: =SUM(F13:F27) -> 0 | G28: =SUM(G13:G27) -> 0 | H28: =SUM(H13:H27) -> 0 | I28: =SUM(I13:I27) -> 0 | J28: =SUM(J13:J27) -> 0 | ... O28: =SUM(O13:O27) -> 435920.25
C30: =C10-C28 -> -23565.431 | D30: =D10-D28 -> -7370.3358 | E30: =E10-E28 -> -19781.897 | F30: =F10-F28 -> 0 | G30: =G10-G28 -> 0 | H30: =H10-H28 -> 0 | I30: =I10-I28 -> 0 | J30: =J10-J28 -> 0 | ... O30: =O10-O28 -> -24096.872

Sheet Expense breakdown
B3: Software expenses - B2B
D4: January | E4: February | F4: March | G4: April | H4: May | I4: June | J4: July | K4: August | L4: September | M4: October | N4: November | O4: December | P4: Total
B5: 1 | C5: JMP Payslips | D5: 8.14 | E5: 8.14 | F5: 8.14 | P5: =SUM(D5:O5) -> 24.42
B6: 2 | C6: Timetastic | D6: 187.36 | E6: 187.36 | F6: 198.39 | P6: =SUM(D6:O6) -> 573.11
B7: 3 | C7: Atlassian | D7: 847.66 | E7: 801.41 | F7: 628.58 | P7: =SUM(D7:O7) -> 2277.65
B8: 4 | C8: MicroSoft | D8: 3371.04 | E8: 3507.61 | F8: 3410.92 | P8: =SUM(D8:O8) -> 10289.57
B9: 5 | C9: Adobe | D9: 366.65 | E9: 366.65 | F9: 366.65 | P9: =SUM(D9:O9) -> 1099.95
B10: 6 | C10: Chat GPT | D10: 79.44 | E10: 77.14 | F10: 79.46 | P10: =SUM(D10:O10) -> 236.04
B11: 7 | C11: MongoDB | D11: 318.45 | E11: 309.91 | F11: 288.5 | P11: =SUM(D11:O11) -> 916.86
B12: 8 | C12: Midjourney | D12: 39.9 | E12: 0 | F12: 79.81 | P12: =SUM(D12:O12) -> 119.71
B13: 9 | C13: Customer.IO | D13: 4881.61 | E13: 5217.05 | F13: 5661.65 | P13: =SUM(D13:O13) -> 15760.31
B14: 10 | C14: IPSTACK | D14: 394.84 | E14: 356.02 | F14: 1421.21 | P14: =SUM(D14:O14) -> 2172.07
B15: 11 | C15: PADDLE.NET | D15: 71.83 | E15: 0 | F15: 0 | P15: =SUM(D15:O15) -> 71.83
B16: 12 | C16: AM.NORD | D16: 892.99 | E16: 4397.3 | F16: 0 | P16: =SUM(D16:O16) -> 5290.29
... B29: 25 | C29: PROTON | D29: 317.35 | E29: 0 | F29: 0 | P29: =SUM(D29:O29) -> 317.35
B30: 26 | C30: SimilarWeb | E30: 5700.5 | F30: 0 | P30: =SUM(D30:O30) -> 5700.5
B31: 27 | C31: DELETETWEETS | E31: 22 | F31: 0 | P31: =SUM(D31:O31) -> 22
B32: 28 | C32: XeroGlobal | E32: 106.53 | F32: 35.42 | P32: =SUM(D32:O32) -> 141.95
B33: 29 | C33: GoDaddy | F33: 603.02 | P33: =SUM(D33:O33) -> 603.02
B34: 30 | C34: Apple Online | F34: 8199 | P34: =SUM(D34:O34) -> 8199
B35: 31 | C35: Anthropic | F35: 39.73 | P35: =SUM(D35:O35) -> 39.73
B36: 32 | C36: THERACINGAPI.COM | F36: 315.15 | P36: =SUM(D36:O36) -> 315.15
P37: =SUM(D37:O37) -> 0
C38: Total in AED | D38: =SUM(D5:D37) -> 43941.66 | E38: =SUM(E5:E37) -> 41607.92 | F38: =SUM(F5:F37) -> 53458.97 | G38: =SUM(G5:G37) -> 0 | H38: =SUM(H5:H37) -> 0 | I38: =SUM(I5:I37) -> 0 | J38: =SUM(J5:J37) -> 0 | K38: =SUM(K5:K37) -> 0 | ... P38: =SUM(P5:P37) -> 139008.55
C39: Total in GBP | D39: =D38/5.04 -> 8718.5833 | E39: =E38/4.95 -> 8405.6404 | F39: =F38/4.85 -> 11022.468 | G39: =G38/5.04 -> 0 | H39: =H38/5.04 -> 0 | I39: =I38/5.04 -> 0 | J39: =J38/5.04 -> 0 | K39: =K38/5.04 -> 0 | L39: =L38/5.04 -> 0 | M39: =M38/5.04 -> 0 | N39: =N38/5.04 -> 0 | O39: =O38/5.04 -> 0 | P39: =SUM(D39:O39) -> 28146.692
B42: Software expenses - B2B
D43: January | E43: February | F43: March | G43: April | H43: May | I43: June | J43: July | K43: August | L43: September | M43: October | N43: November | O43: December | P43: Total
B44: 1 | C44: PA Media | D44: 27264.757 | E44: 27264.757 | F44: 27264.757 | P44: =SUM(D44:O44) -> 81794.27
B45: 2 | C45: AWS | D45: 18269.643 | E45: 18274.539 | F45: 15798.48 | P45: =SUM(D45:O45) -> 52342.663
B46: 3 | C46: Everymatrix | D46: 13043.478 | E46: 13146.363 | F46: 13032.146 | P46: =SUM(D46:O46) -> 39221.987
B47: 4 | C47: Transunion | D47: 2806.5 | E47: 2001 | F47: 2733 | P47: =SUM(D47:O47) -> 7540.5
B48: 5 | C48: NE Room | D48: 24362.609 | E48: 27017.528 | F48: 33020.851 | P48: =SUM(D48:O48) -> 84400.989
B49: 6 | C49: Lukasz | D49: 4782.6087 | E49: 4820.333 | F49: 4778.4535 | P49: =SUM(D49:O49) -> 14381.395
B50: 7 | C50: Lusine | D50: 4173.913 | E50: 4206.8361 | F50: 4170.2867
B51: 8 | C51: Banda Pixels | D51: 7585.1478 | E51: 8107.5723 | F51: 8568.1147
B52: 9 | C52: Data feeds/SportsR | D52: 4347.8261 | E52: 4382.1209 | F52: 4344.0487
P53: =SUM(D53:O53) -> 0
C54: Total in GBP | D54: =SUM(D44:D53) -> 106636.48 | E54: =SUM(E44:E53) -> 109221.05 | F54: =SUM(F44:F53) -> 113710.14 | G54: =SUM(G44:G53) -> 0 | H54: =SUM(H44:H53) -> 0 | I54: =SUM(I44:I53) -> 0 | J54: =SUM(J44:J53) -> 0 | K54: =SUM(K44:K53) -> 0 | ... P54: =SUM(P44:P53) -> 279681.8
B57: Salaries - ZA
D58: January | E58: February | F58: March | G58: April | H58: May | I58: June | J58: July | K58: August | L58: September | M58: October | N58: November | O58: December | P58: Total
...

Sheet Archived
A2: Resources
A3: Operations | C3: =SUM(B4:B6) -> 5300
A4: Chris | B4: 0
A5: Duran | B5: 3050
A6: Shannon | B6: 2250
A7: Trading | C7: =SUM(B8:B12) -> 15650
A8: Nick | B8: 5150
A9: Jermaine | B9: 5150
A10: Dan | B10: 2750
A11: Sifiso | B11: 1300
A12: Ruben | B12: 1300
A13: Casino | C13: =B14 -> 4167
A14: Rob | B14: 4167
A15: Compliance | C15: =SUM(B16:B20) -> 12000
A16: David | B16: 3000
A17: Gaelle | B17: 4000
A18: Christian | B18: 3000
A19: Sam | B19: 1000
A20: Gem | B20: 1000
A21: Customer Service | C21: =SUM(B22:B25) -> 4005
A22: Jason | B22: 1500
A23: Percey | B23: 775
A24: Logan | B24: 865
A25: Nolwazi | B25: 865
A26: Finance | C26: =SUM(B27:B29) -> 4465
A27: Mohammad | B27: 3215
A28: Sandeep | B28: 700
A29: Omkar | B29: 550
A30: Graphics | C30: =B31 -> 2100
A31: Alwyn | B31: 2100
A32: Affiliates | C32: =B33 -> 1750
A33: Mitja | B33: 1750
A36: Endrit | B36: 5545 | C36: EUR
A37: Kastriot | B37: 3034 | C37: EUR
A38: Miran | B38: 2422 | C38: EUR
A39: Adonis | B39: 2177 | C39: EUR
A40: Sheraida | B40: 2422 | C40: EUR
A41: Erijon | B41: 1072 | C41: EUR
A42: Ardian | B42: 2422 | C42: EUR
A43: Dima | B43: 5028 | C43: EUR
...
